<sdf version='1.6'>
  <world name='default'>
    <light name='sun' type='directional'>
      <cast_shadows>1</cast_shadows>
      <pose frame=''>0 0 10 0 -0 0</pose>
      <diffuse>0.8 0.8 0.8 1</diffuse>
      <specular>0.2 0.2 0.2 1</specular>
      <attenuation>
        <range>1000</range>
        <constant>0.9</constant>
        <linear>0.01</linear>
        <quadratic>0.001</quadratic>
      </attenuation>
      <direction>-0.5 0.1 -0.9</direction>
    </light>
    <model name='ground_plane'>
      <static>1</static>
      <link name='link'>
        <collision name='collision'>
          <geometry>
            <plane>
              <normal>0 0 1</normal>
              <size>100 100</size>
            </plane>
          </geometry>
          <surface>
            <contact>
              <collide_bitmask>65535</collide_bitmask>
              <ode/>
            </contact>
            <friction>
              <ode>
                <mu>100</mu>
                <mu2>50</mu2>
              </ode>
              <torsional>
                <ode/>
              </torsional>
            </friction>
            <bounce/>
          </surface>
          <max_contacts>10</max_contacts>
        </collision>
        <visual name='visual'>
          <cast_shadows>0</cast_shadows>
          <geometry>
            <plane>
              <normal>0 0 1</normal>
              <size>100 100</size>
            </plane>
          </geometry>
          <material>
            <script>
              <uri>file://media/materials/scripts/gazebo.material</uri>
              <name>Gazebo/Grey</name>
            </script>
          </material>
        </visual>
        <self_collide>0</self_collide>
        <enable_wind>0</enable_wind>
        <kinematic>0</kinematic>
      </link>
    </model>
    <gravity>0 0 -9.8</gravity>
    <magnetic_field>6e-06 2.3e-05 -4.2e-05</magnetic_field>
    <atmosphere type='adiabatic'/>
    <physics name='default_physics' default='0' type='ode'>
      <max_step_size>0.001</max_step_size>
      <real_time_factor>1</real_time_factor>
      <real_time_update_rate>1000</real_time_update_rate>
    </physics>
    <scene>
      <ambient>0.4 0.4 0.4 1</ambient>
      <background>0.7 0.7 0.7 1</background>
      <shadows>1</shadows>
    </scene>
    <audio>
      <device>default</device>
    </audio>
    <wind/>
    <spherical_coordinates>
      <surface_model>EARTH_WGS84</surface_model>
      <latitude_deg>0</latitude_deg>
      <longitude_deg>0</longitude_deg>
      <elevation>0</elevation>
      <heading_deg>0</heading_deg>
    </spherical_coordinates>
    <model name='rx200'>
      <link name='rx200/base_link'>
        <pose frame=''>0 0 0 0 -0 0</pose>
        <inertial>
          <pose frame=''>-0.035439 -0.003359 0.025341 0 -0 1.5708</pose>
          <mass>0.766135</mass>
          <inertia>
            <ixx>0.003353</ixx>
            <ixy>-0.0001246</ixy>
            <ixz>1.106e-05</ixz>
            <iyy>0.001357</iyy>
            <iyz>0.0002103</iyz>
            <izz>0.004111</izz>
          </inertia>
        </inertial>
        <collision name='rx200/base_link_collision'>
          <pose frame=''>0 0 0 0 0 -1.5708</pose>
          <geometry>
            <mesh>
              <scale>0.001 0.001 0.001</scale>
              <uri>/home/peterjochem/Desktop/Go_Bot/catkin_ws/src/interbotix_ros_arms/interbotix_descriptions/meshes/meshes_rx200/RXA-200-M-1-Base.stl</uri>
            </mesh>
          </geometry>
          <surface>
            <contact>
              <ode/>
            </contact>
            <friction>
              <ode/>
              <torsional>
                <ode/>
              </torsional>
            </friction>
            <bounce/>
          </surface>
          <max_contacts>10</max_contacts>
        </collision>
        <visual name='rx200/base_link_visual'>
          <pose frame=''>0 0 0 0 0 -1.5708</pose>
          <geometry>
            <mesh>
              <scale>0.001 0.001 0.001</scale>
              <uri>/home/peterjochem/Desktop/Go_Bot/catkin_ws/src/interbotix_ros_arms/interbotix_descriptions/meshes/meshes_rx200/RXA-200-M-1-Base.stl</uri>
            </mesh>
          </geometry>
          <material>
            <script>
              <name>Custom/Interbotix</name>
              <uri>file://media/materials/scripts/gazebo.material</uri>
            </script>
          </material>
        </visual>
        <gravity>1</gravity>
        <velocity_decay/>
        <self_collide>0</self_collide>
        <enable_wind>0</enable_wind>
        <kinematic>0</kinematic>
      </link>
      <joint name='fixed' type='fixed'>
        <child>rx200/base_link</child>
        <parent>world</parent>
      </joint>
      <link name='rx200/shoulder_link'>
        <pose frame=''>0 0 0.065 0 -0 0</pose>
        <inertial>
          <pose frame=''>-8.5e-05 1.7e-05 0.013201 0 -0 1.5708</pose>
          <mass>0.257774</mass>
          <inertia>
            <ixx>0.0002663</ixx>
            <ixy>9e-10</ixy>
            <ixz>5.11e-08</ixz>
            <iyy>0.0004428</iyy>
            <iyz>4.416e-07</iyz>
            <izz>0.0004711</izz>
          </inertia>
        </inertial>
        <collision name='rx200/shoulder_link_collision'>
          <pose frame=''>0 0 0.0015 0 0 -1.5708</pose>
          <geometry>
            <mesh>
              <scale>0.001 0.001 0.001</scale>
              <uri>/home/peterjochem/Desktop/Go_Bot/catkin_ws/src/interbotix_ros_arms/interbotix_descriptions/meshes/meshes_rx200/RXA-200-M-2-Shoulder.stl</uri>
            </mesh>
          </geometry>
          <surface>
            <contact>
              <ode/>
            </contact>
            <friction>
              <ode/>
              <torsional>
                <ode/>
              </torsional>
            </friction>
            <bounce/>
          </surface>
          <max_contacts>10</max_contacts>
        </collision>
        <visual name='rx200/shoulder_link_visual'>
          <pose frame=''>0 0 0.0015 0 0 -1.5708</pose>
          <geometry>
            <mesh>
              <scale>0.001 0.001 0.001</scale>
              <uri>/home/peterjochem/Desktop/Go_Bot/catkin_ws/src/interbotix_ros_arms/interbotix_descriptions/meshes/meshes_rx200/RXA-200-M-2-Shoulder.stl</uri>
            </mesh>
          </geometry>
          <material>
            <script>
              <name>Custom/Interbotix</name>
              <uri>file://media/materials/scripts/gazebo.material</uri>
            </script>
          </material>
        </visual>
        <gravity>1</gravity>
        <velocity_decay/>
        <self_collide>0</self_collide>
        <enable_wind>0</enable_wind>
        <kinematic>0</kinematic>
      </link>
      <joint name='waist' type='revolute'>
        <child>rx200/shoulder_link</child>
        <parent>rx200/base_link</parent>
        <axis>
          <xyz>0 0 1</xyz>
          <limit>
            <lower>-3.14159</lower>
            <upper>3.14159</upper>
            <effort>100</effort>
            <velocity>3.14159</velocity>
          </limit>
          <dynamics>
            <spring_reference>0</spring_reference>
            <spring_stiffness>0</spring_stiffness>
          </dynamics>
          <use_parent_model_frame>1</use_parent_model_frame>
        </axis>
      </joint>
      <link name='rx200/upper_arm_link'>
        <pose frame=''>0 0 0.10391 0 -0 0</pose>
        <inertial>
          <pose frame=''>0.011951 -0.000117 0.13943 0 -0 1.5708</pose>
          <mass>0.297782</mass>
          <inertia>
            <ixx>0.00171</ixx>
            <ixy>-9.773e-07</ixy>
            <ixz>2.0936e-06</ixz>
            <iyy>0.001631</iyy>
            <iyz>0.0002132</iyz>
            <izz>0.0001478</izz>
          </inertia>
        </inertial>
        <collision name='rx200/upper_arm_link_collision'>
          <pose frame=''>0 0 0 0 -0 1.5708</pose>
          <geometry>
            <mesh>
              <scale>0.001 0.001 0.001</scale>
              <uri>/home/peterjochem/Desktop/Go_Bot/catkin_ws/src/interbotix_ros_arms/interbotix_descriptions/meshes/meshes_rx200/RXA-200-M-3-UA.stl</uri>
            </mesh>
          </geometry>
          <surface>
            <contact>
              <ode/>
            </contact>
            <friction>
              <ode/>
              <torsional>
                <ode/>
              </torsional>
            </friction>
            <bounce/>
          </surface>
          <max_contacts>10</max_contacts>
        </collision>
        <visual name='rx200/upper_arm_link_visual'>
          <pose frame=''>0 0 0 0 -0 1.5708</pose>
          <geometry>
            <mesh>
              <scale>0.001 0.001 0.001</scale>
              <uri>/home/peterjochem/Desktop/Go_Bot/catkin_ws/src/interbotix_ros_arms/interbotix_descriptions/meshes/meshes_rx200/RXA-200-M-3-UA.stl</uri>
            </mesh>
          </geometry>
          <material>
            <script>
              <name>Custom/Interbotix</name>
              <uri>file://media/materials/scripts/gazebo.material</uri>
            </script>
          </material>
        </visual>
        <gravity>1</gravity>
        <velocity_decay/>
        <self_collide>0</self_collide>
        <enable_wind>0</enable_wind>
        <kinematic>0</kinematic>
      </link>
      <joint name='shoulder' type='revolute'>
        <child>rx200/upper_arm_link</child>
        <parent>rx200/shoulder_link</parent>
        <axis>
          <xyz>0 1 0</xyz>
          <limit>
            <lower>-1.8675</lower>
            <upper>1.93732</upper>
            <effort>100</effort>
            <velocity>1</velocity>
          </limit>
          <dynamics>
            <spring_reference>0</spring_reference>
            <spring_stiffness>0</spring_stiffness>
          </dynamics>
          <use_parent_model_frame>1</use_parent_model_frame>
        </axis>
      </joint>
      <link name='rx200/forearm_link'>
        <pose frame=''>0.05 0 0.30391 -3.14159 -0 0</pose>
        <inertial>
          <pose frame=''>0.114745 -9.4e-05 0 0 -0 1.5708</pose>
          <mass>0.258863</mass>
          <inertia>
            <ixx>0.001055</ixx>
            <ixy>-1.8286e-06</ixy>
            <ixz>0</ixz>
            <iyy>6.421e-05</iyy>
            <iyz>0</iyz>
            <izz>0.001076</izz>
          </inertia>
        </inertial>
        <collision name='rx200/forearm_link_collision'>
          <pose frame=''>0 0 0 0 -0 1.5708</pose>
          <geometry>
            <mesh>
              <scale>0.001 0.001 0.001</scale>
              <uri>/home/peterjochem/Desktop/Go_Bot/catkin_ws/src/interbotix_ros_arms/interbotix_descriptions/meshes/meshes_rx200/RXA-200-M-4-Forearm.stl</uri>
            </mesh>
          </geometry>
          <surface>
            <contact>
              <ode/>
            </contact>
            <friction>
              <ode/>
              <torsional>
                <ode/>
              </torsional>
            </friction>
            <bounce/>
          </surface>
          <max_contacts>10</max_contacts>
        </collision>
        <visual name='rx200/forearm_link_visual'>
          <pose frame=''>0 0 0 0 -0 1.5708</pose>
          <geometry>
            <mesh>
              <scale>0.001 0.001 0.001</scale>
              <uri>/home/peterjochem/Desktop/Go_Bot/catkin_ws/src/interbotix_ros_arms/interbotix_descriptions/meshes/meshes_rx200/RXA-200-M-4-Forearm.stl</uri>
            </mesh>
          </geometry>
          <material>
            <script>
              <name>Custom/Interbotix</name>
              <uri>file://media/materials/scripts/gazebo.material</uri>
            </script>
          </material>
        </visual>
        <gravity>1</gravity>
        <velocity_decay/>
        <self_collide>0</self_collide>
        <enable_wind>0</enable_wind>
        <kinematic>0</kinematic>
      </link>
      <joint name='elbow' type='revolute'>
        <child>rx200/forearm_link</child>
        <parent>rx200/upper_arm_link</parent>
        <axis>
          <xyz>0 -1 -0</xyz>
          <limit>
            <lower>-1.62316</lower>
            <upper>1.88496</upper>
            <effort>100</effort>
            <velocity>3.14159</velocity>
          </limit>
          <dynamics>
            <spring_reference>0</spring_reference>
            <spring_stiffness>0</spring_stiffness>
          </dynamics>
          <use_parent_model_frame>1</use_parent_model_frame>
        </axis>
      </joint>
      <link name='rx200/wrist_link'>
        <pose frame=''>0.25 0 0.30391 -3.14159 -0 0</pose>
        <inertial>
          <pose frame=''>0.04236 1e-05 -0.010577 -3.14159 -0 -1.5708</pose>
          <mass>0.084957</mass>
          <inertia>
            <ixx>3.082e-05</ixx>
            <ixy>1.91e-08</ixy>
            <ixz>2.3e-09</ixz>
            <iyy>2.822e-05</iyy>
            <iyz>2.5481e-06</iyz>
            <izz>3.152e-05</izz>
          </inertia>
        </inertial>
        <collision name='rx200/wrist_link_collision'>
          <pose frame=''>0 0 0 -3.14159 -0 -1.5708</pose>
          <geometry>
            <mesh>
              <scale>0.001 0.001 0.001</scale>
              <uri>/home/peterjochem/Desktop/Go_Bot/catkin_ws/src/interbotix_ros_arms/interbotix_descriptions/meshes/meshes_rx200/RXA-200-M-5-Wrist.stl</uri>
            </mesh>
          </geometry>
          <surface>
            <contact>
              <ode/>
            </contact>
            <friction>
              <ode/>
              <torsional>
                <ode/>
              </torsional>
            </friction>
            <bounce/>
          </surface>
          <max_contacts>10</max_contacts>
        </collision>
        <visual name='rx200/wrist_link_visual'>
          <pose frame=''>0 0 0 -3.14159 -0 -1.5708</pose>
          <geometry>
            <mesh>
              <scale>0.001 0.001 0.001</scale>
              <uri>/home/peterjochem/Desktop/Go_Bot/catkin_ws/src/interbotix_ros_arms/interbotix_descriptions/meshes/meshes_rx200/RXA-200-M-5-Wrist.stl</uri>
            </mesh>
          </geometry>
          <material>
            <script>
              <name>Custom/Interbotix</name>
              <uri>file://media/materials/scripts/gazebo.material</uri>
            </script>
          </material>
        </visual>
        <gravity>1</gravity>
        <velocity_decay/>
        <self_collide>0</self_collide>
        <enable_wind>0</enable_wind>
        <kinematic>0</kinematic>
      </link>
      <joint name='wrist_angle' type='revolute'>
        <child>rx200/wrist_link</child>
        <parent>rx200/forearm_link</parent>
        <axis>
          <xyz>0 -1 -0</xyz>
          <limit>
            <lower>-2.14675</lower>
            <upper>1.74533</upper>
            <effort>100</effort>
            <velocity>3.14159</velocity>
          </limit>
          <dynamics>
            <spring_reference>0</spring_reference>
            <spring_stiffness>0</spring_stiffness>
          </dynamics>
          <use_parent_model_frame>1</use_parent_model_frame>
        </axis>
      </joint>
      <link name='rx200/gripper_link'>
        <pose frame=''>0.315 0 0.30391 0 -0 0</pose>
        <inertial>
          <pose frame=''>0.02163 0 0.01141 0 -0 1.5708</pose>
          <mass>0.072885</mass>
          <inertia>
            <ixx>2.537e-05</ixx>
            <ixy>0</ixy>
            <ixz>0</ixz>
            <iyy>1.836e-05</iyy>
            <iyz>4.34e-07</iyz>
            <izz>1.674e-05</izz>
          </inertia>
        </inertial>
        <collision name='rx200/gripper_link_collision'>
          <pose frame=''>-0.02 0 0 0 -0 1.5708</pose>
          <geometry>
            <mesh>
              <scale>0.001 0.001 0.001</scale>
              <uri>/home/peterjochem/Desktop/Go_Bot/catkin_ws/src/interbotix_ros_arms/interbotix_descriptions/meshes/meshes_rx200/RXA-200-M-6-Gripper.stl</uri>
            </mesh>
          </geometry>
          <surface>
            <contact>
              <ode/>
            </contact>
            <friction>
              <ode/>
              <torsional>
                <ode/>
              </torsional>
            </friction>
            <bounce/>
          </surface>
          <max_contacts>10</max_contacts>
        </collision>
        <visual name='rx200/gripper_link_visual'>
          <pose frame=''>-0.02 0 0 0 -0 1.5708</pose>
          <geometry>
            <mesh>
              <scale>0.001 0.001 0.001</scale>
              <uri>/home/peterjochem/Desktop/Go_Bot/catkin_ws/src/interbotix_ros_arms/interbotix_descriptions/meshes/meshes_rx200/RXA-200-M-6-Gripper.stl</uri>
            </mesh>
          </geometry>
          <material>
            <script>
              <name>Custom/Interbotix</name>
              <uri>file://media/materials/scripts/gazebo.material</uri>
            </script>
          </material>
        </visual>
        <gravity>1</gravity>
        <velocity_decay/>
        <self_collide>0</self_collide>
        <enable_wind>0</enable_wind>
        <kinematic>0</kinematic>
      </link>
      <joint name='wrist_rotate' type='revolute'>
        <child>rx200/gripper_link</child>
        <parent>rx200/wrist_link</parent>
        <axis>
          <xyz>1 0 0</xyz>
          <limit>
            <lower>-3.14159</lower>
            <upper>3.14159</upper>
            <effort>100</effort>
            <velocity>3.14159</velocity>
          </limit>
          <dynamics>
            <spring_reference>0</spring_reference>
            <spring_stiffness>0</spring_stiffness>
          </dynamics>
          <use_parent_model_frame>1</use_parent_model_frame>
        </axis>
      </joint>
      <link name='rx200/ee_arm_link'>
        <pose frame=''>0.358 0 0.30391 0 -0 0</pose>
        <inertial>
          <pose frame=''>0 0 0 0 -0 0</pose>
          <mass>0.001</mass>
          <inertia>
            <ixx>0.001</ixx>
            <ixy>0</ixy>
            <ixz>0</ixz>
            <iyy>0.001</iyy>
            <iyz>0</iyz>
            <izz>0.001</izz>
          </inertia>
        </inertial>
        <self_collide>0</self_collide>
        <enable_wind>0</enable_wind>
        <kinematic>0</kinematic>
      </link>
      <joint name='ee_arm' type='revolute'>
        <child>rx200/ee_arm_link</child>
        <parent>rx200/gripper_link</parent>
        <axis>
          <limit>
            <lower>0</lower>
            <upper>0</upper>
          </limit>
          <dynamics>
            <damping>0</damping>
            <friction>0</friction>
            <spring_reference>0</spring_reference>
            <spring_stiffness>0</spring_stiffness>
          </dynamics>
          <use_parent_model_frame>1</use_parent_model_frame>
          <xyz>0 0 1</xyz>
        </axis>
        <physics>
          <ode>
            <limit>
              <cfm>0</cfm>
              <erp>0.2</erp>
            </limit>
          </ode>
        </physics>
      </joint>
      <link name='rx200/gripper_prop_link'>
        <pose frame=''>0.3635 0 0.30391 0 -0 0</pose>
        <inertial>
          <pose frame=''>0.000846 -2e-06 4.2e-05 0 -0 1.5708</pose>
          <mass>0.00434</mass>
          <inertia>
            <ixx>5.923e-07</ixx>
            <ixy>0</ixy>
            <ixz>3.195e-07</ixz>
            <iyy>1.1156e-06</iyy>
            <iyz>-4e-10</iyz>
            <izz>5.743e-07</izz>
          </inertia>
        </inertial>
        <collision name='rx200/gripper_prop_link_collision'>
          <pose frame=''>-0.0685 0 0 0 -0 1.5708</pose>
          <geometry>
            <mesh>
              <scale>0.001 0.001 0.001</scale>
              <uri>/home/peterjochem/Desktop/Go_Bot/catkin_ws/src/interbotix_ros_arms/interbotix_descriptions/meshes/meshes_rx200/RXA-200-M-7-Gripper-Prop.stl</uri>
            </mesh>
          </geometry>
          <surface>
            <contact>
              <ode/>
            </contact>
            <friction>
              <ode/>
              <torsional>
                <ode/>
              </torsional>
            </friction>
            <bounce/>
          </surface>
          <max_contacts>10</max_contacts>
        </collision>
        <visual name='rx200/gripper_prop_link_visual'>
          <pose frame=''>-0.0685 0 0 0 -0 1.5708</pose>
          <geometry>
            <mesh>
              <scale>0.001 0.001 0.001</scale>
              <uri>/home/peterjochem/Desktop/Go_Bot/catkin_ws/src/interbotix_ros_arms/interbotix_descriptions/meshes/meshes_rx200/RXA-200-M-7-Gripper-Prop.stl</uri>
            </mesh>
          </geometry>
          <material>
            <script>
              <name>Custom/Interbotix</name>
              <uri>file://media/materials/scripts/gazebo.material</uri>
            </script>
          </material>
        </visual>
        <gravity>1</gravity>
        <velocity_decay>
          <linear>1</linear>
          <angular>1</angular>
        </velocity_decay>
        <self_collide>0</self_collide>
        <enable_wind>0</enable_wind>
        <kinematic>0</kinematic>
      </link>
      <joint name='gripper' type='revolute'>
        <child>rx200/gripper_prop_link</child>
        <parent>rx200/ee_arm_link</parent>
        <axis>
          <xyz>1 0 0</xyz>
          <limit>
            <lower>-1e+16</lower>
            <upper>1e+16</upper>
          </limit>
          <dynamics>
            <spring_reference>0</spring_reference>
            <spring_stiffness>0</spring_stiffness>
          </dynamics>
          <use_parent_model_frame>1</use_parent_model_frame>
        </axis>
      </joint>
      <link name='rx200/gripper_bar_link'>
        <pose frame=''>0.358 0 0.30391 0 -0 0</pose>
        <inertial>
          <pose frame=''>0.009687 1e-06 0.004962 0 -0 1.5708</pose>
          <mass>0.034199</mass>
          <inertia>
            <ixx>7.4125e-06</ixx>
            <ixy>-8e-10</ixy>
            <ixz>-6e-10</ixz>
            <iyy>2.843e-05</iyy>
            <iyz>-1.3889e-06</iyz>
            <izz>2.86e-05</izz>
          </inertia>
        </inertial>
        <collision name='rx200/gripper_bar_link_collision'>
          <pose frame=''>-0.063 0 0 0 -0 1.5708</pose>
          <geometry>
            <mesh>
              <scale>0.001 0.001 0.001</scale>
              <uri>/home/peterjochem/Desktop/Go_Bot/catkin_ws/src/interbotix_ros_arms/interbotix_descriptions/meshes/meshes_rx200/RXA-200-M-8-Gripper-Bar.stl</uri>
            </mesh>
          </geometry>
          <surface>
            <contact>
              <ode/>
            </contact>
            <friction>
              <ode/>
              <torsional>
                <ode/>
              </torsional>
            </friction>
            <bounce/>
          </surface>
          <max_contacts>10</max_contacts>
        </collision>
        <visual name='rx200/gripper_bar_link_visual'>
          <pose frame=''>-0.063 0 0 0 -0 1.5708</pose>
          <geometry>
            <mesh>
              <scale>0.001 0.001 0.001</scale>
              <uri>/home/peterjochem/Desktop/Go_Bot/catkin_ws/src/interbotix_ros_arms/interbotix_descriptions/meshes/meshes_rx200/RXA-200-M-8-Gripper-Bar.stl</uri>
            </mesh>
          </geometry>
          <material>
            <script>
              <name>Custom/Interbotix</name>
              <uri>file://media/materials/scripts/gazebo.material</uri>
            </script>
          </material>
        </visual>
        <gravity>1</gravity>
        <velocity_decay/>
        <self_collide>0</self_collide>
        <enable_wind>0</enable_wind>
        <kinematic>0</kinematic>
      </link>
      <joint name='gripper_bar' type='revolute'>
        <child>rx200/gripper_bar_link</child>
        <parent>rx200/ee_arm_link</parent>
        <axis>
          <limit>
            <lower>0</lower>
            <upper>0</upper>
          </limit>
          <dynamics>
            <damping>0</damping>
            <friction>0</friction>
            <spring_reference>0</spring_reference>
            <spring_stiffness>0</spring_stiffness>
          </dynamics>
          <use_parent_model_frame>1</use_parent_model_frame>
          <xyz>0 0 1</xyz>
        </axis>
        <physics>
          <ode>
            <limit>
              <cfm>0</cfm>
              <erp>0.2</erp>
            </limit>
          </ode>
        </physics>
      </joint>
      <link name='rx200/fingers_link'>
        <pose frame=''>0.381 0 0.30391 0 -0 0</pose>
        <inertial>
          <pose frame=''>0 0 0 0 -0 0</pose>
          <mass>0.001</mass>
          <inertia>
            <ixx>0.001</ixx>
            <ixy>0</ixy>
            <ixz>0</ixz>
            <iyy>0.001</iyy>
            <iyz>0</iyz>
            <izz>0.001</izz>
          </inertia>
        </inertial>
        <self_collide>0</self_collide>
        <enable_wind>0</enable_wind>
        <kinematic>0</kinematic>
      </link>
      <joint name='ee_bar' type='revolute'>
        <child>rx200/fingers_link</child>
        <parent>rx200/gripper_bar_link</parent>
        <axis>
          <limit>
            <lower>0</lower>
            <upper>0</upper>
          </limit>
          <dynamics>
            <damping>0</damping>
            <friction>0</friction>
            <spring_reference>0</spring_reference>
            <spring_stiffness>0</spring_stiffness>
          </dynamics>
          <use_parent_model_frame>1</use_parent_model_frame>
          <xyz>0 0 1</xyz>
        </axis>
        <physics>
          <ode>
            <limit>
              <cfm>0</cfm>
              <erp>0.2</erp>
            </limit>
          </ode>
        </physics>
      </joint>
      <link name='rx200/ee_gripper_link'>
        <pose frame=''>0.408575 0 0.30391 0 -0 0</pose>
        <inertial>
          <pose frame=''>0 0 0 0 -0 0</pose>
          <mass>0.001</mass>
          <inertia>
            <ixx>0.001</ixx>
            <ixy>0</ixy>
            <ixz>0</ixz>
            <iyy>0.001</iyy>
            <iyz>0</iyz>
            <izz>0.001</izz>
          </inertia>
        </inertial>
        <self_collide>0</self_collide>
        <enable_wind>0</enable_wind>
        <kinematic>0</kinematic>
      </link>
      <joint name='ee_gripper' type='revolute'>
        <child>rx200/ee_gripper_link</child>
        <parent>rx200/fingers_link</parent>
        <axis>
          <limit>
            <lower>0</lower>
            <upper>0</upper>
          </limit>
          <dynamics>
            <damping>0</damping>
            <friction>0</friction>
            <spring_reference>0</spring_reference>
            <spring_stiffness>0</spring_stiffness>
          </dynamics>
          <use_parent_model_frame>1</use_parent_model_frame>
          <xyz>0 0 1</xyz>
        </axis>
        <physics>
          <ode>
            <limit>
              <cfm>0</cfm>
              <erp>0.2</erp>
            </limit>
          </ode>
        </physics>
      </joint>
      <link name='rx200/left_finger_link'>
        <pose frame=''>0.381 0 0.30391 0 -0 0</pose>
        <inertial>
          <pose frame=''>0.013816 0 0 0 -0 -1.5708</pose>
          <mass>0.016246</mass>
          <inertia>
            <ixx>4.731e-06</ixx>
            <ixy>-4.56e-07</ixy>
            <ixz>0</ixz>
            <iyy>1.5506e-06</iyy>
            <iyz>0</iyz>
            <izz>3.7467e-06</izz>
          </inertia>
        </inertial>
        <collision name='rx200/left_finger_link_collision'>
          <pose frame=''>0 0.005 0 0 -0 3.14159</pose>
          <geometry>
            <mesh>
              <scale>0.001 0.001 0.001</scale>
              <uri>/home/peterjochem/Desktop/Go_Bot/catkin_ws/src/interbotix_ros_arms/interbotix_descriptions/meshes/meshes_rx200/RXA-200-M-9-Finger.stl</uri>
            </mesh>
          </geometry>
          <surface>
            <contact>
              <ode>
                <kp>1e+06</kp>
                <kd>1</kd>
                <max_vel>0</max_vel>
                <min_depth>0.001</min_depth>
              </ode>
            </contact>
            <friction>
              <ode>
                <mu>50</mu>
                <mu2>50</mu2>
              </ode>
              <torsional>
                <ode/>
              </torsional>
            </friction>
            <bounce/>
          </surface>
          <max_contacts>10</max_contacts>
        </collision>
        <visual name='rx200/left_finger_link_visual'>
          <pose frame=''>0 0.005 0 0 -0 3.14159</pose>
          <geometry>
            <mesh>
              <scale>0.001 0.001 0.001</scale>
              <uri>/home/peterjochem/Desktop/Go_Bot/catkin_ws/src/interbotix_ros_arms/interbotix_descriptions/meshes/meshes_rx200/RXA-200-M-9-Finger.stl</uri>
            </mesh>
          </geometry>
          <material>
            <script>
              <name>Custom/Interbotix</name>
              <uri>file://media/materials/scripts/gazebo.material</uri>
            </script>
          </material>
        </visual>
        <velocity_decay/>
        <gravity>1</gravity>
        <velocity_decay/>
        <self_collide>0</self_collide>
        <enable_wind>0</enable_wind>
        <kinematic>0</kinematic>
      </link>
      <joint name='left_finger' type='prismatic'>
        <child>rx200/left_finger_link</child>
        <parent>rx200/fingers_link</parent>
        <axis>
          <xyz>0 1 0</xyz>
          <limit>
            <lower>0.015</lower>
            <upper>0.037</upper>
            <effort>10</effort>
            <velocity>1</velocity>
          </limit>
          <dynamics>
            <spring_reference>0</spring_reference>
            <spring_stiffness>0</spring_stiffness>
          </dynamics>
          <use_parent_model_frame>1</use_parent_model_frame>
        </axis>
      </joint>
      <link name='rx200/right_finger_link'>
        <pose frame=''>0.381 0 0.30391 0 -0 0</pose>
        <inertial>
          <pose frame=''>0.013816 0 0 -3.14159 -0 -1.5708</pose>
          <mass>0.016246</mass>
          <inertia>
            <ixx>4.731e-06</ixx>
            <ixy>4.56e-07</ixy>
            <ixz>0</ixz>
            <iyy>1.5506e-06</iyy>
            <iyz>0</iyz>
            <izz>3.7467e-06</izz>
          </inertia>
        </inertial>
        <collision name='rx200/right_finger_link_collision'>
          <pose frame=''>0 -0.005 0 3.14159 -0 3.14159</pose>
          <geometry>
            <mesh>
              <scale>0.001 0.001 0.001</scale>
              <uri>/home/peterjochem/Desktop/Go_Bot/catkin_ws/src/interbotix_ros_arms/interbotix_descriptions/meshes/meshes_rx200/RXA-200-M-9-Finger.stl</uri>
            </mesh>
          </geometry>
          <surface>
            <contact>
              <ode>
                <kp>1e+06</kp>
                <kd>1</kd>
                <max_vel>0</max_vel>
                <min_depth>0.001</min_depth>
              </ode>
            </contact>
            <friction>
              <ode>
                <mu>500</mu>
                <mu2>500</mu2>
              </ode>
              <torsional>
                <ode/>
              </torsional>
            </friction>
            <bounce/>
          </surface>
          <max_contacts>10</max_contacts>
        </collision>
        <visual name='rx200/right_finger_link_visual'>
          <pose frame=''>0 -0.005 0 3.14159 -0 3.14159</pose>
          <geometry>
            <mesh>
              <scale>0.001 0.001 0.001</scale>
              <uri>/home/peterjochem/Desktop/Go_Bot/catkin_ws/src/interbotix_ros_arms/interbotix_descriptions/meshes/meshes_rx200/RXA-200-M-9-Finger.stl</uri>
            </mesh>
          </geometry>
          <material>
            <script>
              <name>Custom/Interbotix</name>
              <uri>file://media/materials/scripts/gazebo.material</uri>
            </script>
          </material>
        </visual>
        <velocity_decay/>
        <gravity>1</gravity>
        <velocity_decay/>
        <self_collide>0</self_collide>
        <enable_wind>0</enable_wind>
        <kinematic>0</kinematic>
      </link>
      <joint name='right_finger' type='prismatic'>
        <child>rx200/right_finger_link</child>
        <parent>rx200/fingers_link</parent>
        <axis>
          <xyz>0 1 0</xyz>
          <limit>
            <lower>-0.037</lower>
            <upper>-0.015</upper>
            <effort>10</effort>
            <velocity>1</velocity>
          </limit>
          <dynamics>
            <spring_reference>0</spring_reference>
            <spring_stiffness>0</spring_stiffness>
          </dynamics>
          <use_parent_model_frame>1</use_parent_model_frame>
        </axis>
      </joint>
      <static>0</static>
      <plugin name='gazebo_ros_control' filename='libgazebo_ros_control.so'>
        <robotSimType>gazebo_ros_control/DefaultRobotHWSim</robotSimType>
        <legacyModeNS>1</legacyModeNS>
        <robotNamespace>/rx200/</robotNamespace>
      </plugin>
      <pose frame=''>0 0 0 0 -0 0</pose>
    </model>
    <model name='chessboard'>
      <link name='link'>
        <inertial>
          <mass>0.05</mass>
          <inertia>
            <ixx>0.0015</ixx>
            <ixy>0.1</ixy>
            <ixz>0.1</ixz>
            <iyy>0.0015</iyy>
            <iyz>0.1</iyz>
            <izz>0.00108</izz>
          </inertia>
        </inertial>
        <velocity_decay>
          <linear>0.1</linear>
          <angular>0.1</angular>
        </velocity_decay>
        <self_collide>0</self_collide>
        <kinematic>0</kinematic>
        <gravity>1</gravity>
        <enable_wind>0</enable_wind>
        <pose frame=''>0 0 0 0 -0 0</pose>
        <visual name='visual1'>
          <pose frame=''>0 0 0 0 -0 0</pose>
          <geometry>
            <mesh>
              <uri>model://chessboard/meshes/chessboard.dae</uri>
              <scale>8.4 8.4 0.4</scale>
            </mesh>
          </geometry>
          <transparency>0</transparency>
          <cast_shadows>1</cast_shadows>
        </visual>
        <collision name='colision'>
          <laser_retro>0</laser_retro>
          <max_contacts>10</max_contacts>
          <pose frame=''>0 0 0 0 -0 0</pose>
          <geometry>
            <box>
              <size>0.42 0.42 0.02</size>
            </box>
          </geometry>
          <surface>
            <friction>
              <ode>
                <mu>3e+07</mu>
                <mu2>3e+06</mu2>
                <fdir1>0 0 0</fdir1>
                <slip1>0</slip1>
                <slip2>0</slip2>
              </ode>
              <torsional>
                <coefficient>1</coefficient>
                <patch_radius>0</patch_radius>
                <surface_radius>0</surface_radius>
                <use_patch_radius>1</use_patch_radius>
                <ode>
                  <slip>0</slip>
                </ode>
              </torsional>
            </friction>
            <bounce>
              <restitution_coefficient>0</restitution_coefficient>
              <threshold>1e+06</threshold>
            </bounce>
            <contact>
              <collide_without_contact>0</collide_without_contact>
              <collide_without_contact_bitmask>1</collide_without_contact_bitmask>
              <collide_bitmask>1</collide_bitmask>
              <ode>
                <soft_cfm>0</soft_cfm>
                <soft_erp>0.2</soft_erp>
                <kp>1e+09</kp>
                <kd>1e+06</kd>
                <max_vel>0.1</max_vel>
                <min_depth>0.0025</min_depth>
              </ode>
              <bullet>
                <split_impulse>1</split_impulse>
                <split_impulse_penetration_threshold>-0.01</split_impulse_penetration_threshold>
                <soft_cfm>0</soft_cfm>
                <soft_erp>0.2</soft_erp>
                <kp>1e+09</kp>
                <kd>1e+06</kd>
              </bullet>
            </contact>
          </surface>
        </collision>
      </link>
      <static>0</static>
      <allow_auto_disable>1</allow_auto_disable>
      <pose frame=''>0.329083 0.008315 0 0 -0 0</pose>
    </model>
    <state world_name='default'>
      <sim_time>1066 702000000</sim_time>
      <real_time>838 216495000</real_time>
      <wall_time>1616944549 427277186</wall_time>
      <iterations>813987</iterations>
      <model name='chessboard'>
        <pose frame=''>0.313784 -0.004845 0.007521 0 -0 0</pose>
        <scale>1 1 1</scale>
        <link name='link'>
          <pose frame=''>0.313784 -0.004845 0.007521 0 -0 0</pose>
          <velocity>0 0 0 0 -0 0</velocity>
          <acceleration>0.000673 -0.000458 0.012683 0.045736 0.067216 1e-06</acceleration>
          <wrench>3.4e-05 -2.3e-05 0.000634 0 -0 0</wrench>
        </link>
      </model>
      <model name='ground_plane'>
        <pose frame=''>0 0 0 0 -0 0</pose>
        <scale>1 1 1</scale>
        <link name='link'>
          <pose frame=''>0 0 0 0 -0 0</pose>
          <velocity>0 0 0 0 -0 0</velocity>
          <acceleration>0 0 0 0 -0 0</acceleration>
          <wrench>0 0 0 0 -0 0</wrench>
        </link>
      </model>
      <model name='rx200'>
        <pose frame=''>-0 -0 0 0 -0 0</pose>
        <scale>1 1 1</scale>
        <link name='rx200/base_link'>
          <pose frame=''>-0 -0 0 0 -0 0</pose>
          <velocity>-0 -0 -1e-06 -3.5e-05 3e-06 0</velocity>
          <acceleration>-0.000113 0.00146 -0.001878 -0.064814 0.005542 -0.002372</acceleration>
          <wrench>-8.7e-05 0.001119 -0.001439 0 -0 0</wrench>
        </link>
        <link name='rx200/ee_arm_link'>
          <pose frame=''>0.299384 -0.089665 0.180036 0.029694 1.54969 -0.290724</pose>
          <velocity>-1.3e-05 -3.3e-05 -1e-06 -0.001732 0.000564 -7.3e-05</velocity>
          <acceleration>-0.021357 -0.05711 0.000433 1.5775 1.54749 -0.180856</acceleration>
          <wrench>-2.1e-05 -5.7e-05 0 0 -0 0</wrench>
        </link>
        <link name='rx200/ee_gripper_link'>
          <pose frame=''>0.300406 -0.08997 0.129451 0.029734 1.54967 -0.290684</pose>
          <velocity>7e-06 2.3e-05 3e-06 0.001828 -0.000621 7.3e-05</velocity>
          <acceleration>-0.00292 -0.00527 0.007126 2.38979 -0.782525 0.108855</acceleration>
          <wrench>-3e-06 -5e-06 7e-06 0 -0 0</wrench>
        </link>
        <link name='rx200/fingers_link'>
          <pose frame=''>0.299849 -0.089803 0.15703 0.029735 1.54967 -0.290683</pose>
          <velocity>-1.1e-05 -3e-05 -1e-06 0.00186 -0.000632 7.2e-05</velocity>
          <acceleration>-0.025853 -0.077163 0.000139 2.44797 -0.802025 0.107046</acceleration>
          <wrench>-2.6e-05 -7.7e-05 0 0 -0 0</wrench>
        </link>
        <link name='rx200/forearm_link'>
          <pose frame=''>0.105851 -0.031703 0.277951 -3.14159 -0.050302 -0.290997</pose>
          <velocity>4e-06 1.2e-05 -2e-06 -5.7e-05 1.1e-05 -4.1e-05</velocity>
          <acceleration>0.005608 0.015068 -0.00134 -0.196581 -1.01395 0.695735</acceleration>
          <wrench>0.001452 0.003901 -0.000347 0 -0 0</wrench>
        </link>
        <link name='rx200/gripper_bar_link'>
          <pose frame=''>0.299383 -0.089664 0.180023 0.029702 1.54969 -0.290716</pose>
          <velocity>-2e-06 -3e-06 -0 -0.001215 0.000395 -4.9e-05</velocity>
          <acceleration>-0.010754 -0.030105 0.001857 -1.31633 -1.12403 2.6497</acceleration>
          <wrench>-0.000368 -0.00103 6.3e-05 0 -0 0</wrench>
        </link>
        <link name='rx200/gripper_link'>
          <pose frame=''>0.298515 -0.089405 0.223022 0.029655 1.5497 -0.290762</pose>
          <velocity>-8e-06 -1.7e-05 -1e-06 -0.000122 2.1e-05 9e-06</velocity>
          <acceleration>-0.012712 -0.030898 0.000995 -0.182139 0.039618 0.075606</acceleration>
          <wrench>-0.000927 -0.002252 7.3e-05 0 -0 0</wrench>
        </link>
        <link name='rx200/gripper_prop_link'>
          <pose frame=''>0.299494 -0.089697 0.174519 3.09447 1.54969 -0.290725</pose>
          <velocity>3e-06 1.1e-05 -1e-06 -0.001784 0.000594 0.001678</velocity>
          <acceleration>0.007821 0.023997 0.001317 -1.46443 0.31328 -2.90996</acceleration>
          <wrench>3.4e-05 0.000104 6e-06 0 -0 0</wrench>
        </link>
        <link name='rx200/left_finger_link'>
          <pose frame=''>0.304574 -0.075563 0.157031 0.029263 1.54967 -0.291154</pose>
          <velocity>-1.1e-05 -2.8e-05 3.2e-05 0.001853 -0.000628 7.7e-05</velocity>
          <acceleration>-0.000928 0.003624 0.045558 0.778312 -0.600506 0.161422</acceleration>
          <wrench>-1.5e-05 5.9e-05 0.00074 0 -0 0</wrench>
        </link>
        <link name='rx200/right_finger_link'>
          <pose frame=''>0.29512 -0.104052 0.157018 0.029983 1.54967 -0.290436</pose>
          <velocity>-9e-06 -2.9e-05 -2.8e-05 0.001847 -0.000628 7.5e-05</velocity>
          <acceleration>0.003475 0.002215 -0.032726 0.770983 -0.602595 0.151915</acceleration>
          <wrench>5.6e-05 3.6e-05 -0.000532 0 -0 0</wrench>
        </link>
        <link name='rx200/shoulder_link'>
          <pose frame=''>-0 -0 0.065 0 -0 -0.290999</pose>
          <velocity>0 2e-06 -1e-06 -4.5e-05 6e-06 -2.3e-05</velocity>
          <acceleration>0.000323 0.004823 -0.002437 -1.55642 -1.12556 0.933264</acceleration>
          <wrench>8.3e-05 0.001243 -0.000628 0 -0 0</wrench>
        </link>
        <link name='rx200/upper_arm_link'>
          <pose frame=''>-0 -0 0.10391 2e-06 0.320701 -0.290998</pose>
          <velocity>1e-06 5e-06 -2e-06 -5.9e-05 2.3e-05 -2.7e-05</velocity>
          <acceleration>0.00559 0.017206 -0.003469 -2.68451 -0.855834 1.67036</acceleration>
          <wrench>0.001665 0.005124 -0.001033 0 -0 0</wrench>
        </link>
        <link name='rx200/wrist_link'>
          <pose frame=''>0.297201 -0.089012 0.288007 -3.14148 1.5497 -0.290884</pose>
          <velocity>-1e-06 -2e-06 -1e-06 -7.3e-05 4.8e-05 -4e-05</velocity>
          <acceleration>-0.003067 -0.005331 0.000545 0.07148 0.597133 1.25772</acceleration>
          <wrench>-0.000261 -0.000453 4.6e-05 0 -0 0</wrench>
        </link>
      </model>
      <light name='sun'>
        <pose frame=''>0 0 10 0 -0 0</pose>
      </light>
    </state>
    <gui fullscreen='0'>
      <camera name='user_camera'>
        <pose frame=''>0.985737 0.007996 0.25581 -0 0.195837 -3.10619</pose>
        <view_controller>orbit</view_controller>
        <projection_type>perspective</projection_type>
      </camera>
    </gui>
  </world>
</sdf>
